<?xml version="1.0" ?>
<robot name="ERC22_URDF" xmlns:xacro="http://www.ros.org/wiki/xacro">

<xacro:include filename="$(find ERC22_URDF_description)/urdf/materials.xacro" />
<xacro:include filename="$(find ERC22_URDF_description)/urdf/ERC22_URDF.trans" />
<xacro:include filename="$(find ERC22_URDF_description)/urdf/ERC22_URDF.gazebo" />
<link name="base_link">
  <inertial>
    <origin xyz="0.009439051177251773 0.0008928693179034862 0.4515443268163816" rpy="0 0 0"/>
    <mass value="1.7296802386297903"/>
    <inertia ixx="0.122252" iyy="0.093075" izz="0.197741" ixy="-4.9e-05" iyz="2.2e-05" ixz="0.005471"/>
  </inertial>
  <visual>
    <origin xyz="0 0 0" rpy="0 0 0"/>
    <geometry>
      <mesh filename="package://ERC22_URDF_description/meshes/base_link.stl" scale="0.001 0.001 0.001"/>
    </geometry>
    <material name="silver"/>
  </visual>
  <collision>
    <origin xyz="0 0 0" rpy="0 0 0"/>
    <geometry>
      <mesh filename="package://ERC22_URDF_description/meshes/base_link.stl" scale="0.001 0.001 0.001"/>
    </geometry>
  </collision>
</link>

<link name="WLF_supp_1">
  <inertial>
    <origin xyz="0.0010155899598203177 0.04456811672884159 -0.069974852362928" rpy="0 0 0"/>
    <mass value="0.040963207008450755"/>
    <inertia ixx="0.000114" iyy="9.6e-05" izz="3e-05" ixy="-0.0" iyz="1.6e-05" ixz="1e-06"/>
  </inertial>
  <visual>
    <origin xyz="-0.393441 0.383158 -0.365642" rpy="0 0 0"/>
    <geometry>
      <mesh filename="package://ERC22_URDF_description/meshes/WLF_supp_1.stl" scale="0.001 0.001 0.001"/>
    </geometry>
    <material name="silver"/>
  </visual>
  <collision>
    <origin xyz="-0.393441 0.383158 -0.365642" rpy="0 0 0"/>
    <geometry>
      <mesh filename="package://ERC22_URDF_description/meshes/WLF_supp_1.stl" scale="0.001 0.001 0.001"/>
    </geometry>
  </collision>
</link>

<link name="Left_leg_double_1">
  <inertial>
    <origin xyz="-0.015583210905782074 -0.06278452280466362 -0.07532072866040473" rpy="0 0 0"/>
    <mass value="0.15830687785841724"/>
    <inertia ixx="0.000712" iyy="0.003257" izz="0.002676" ixy="-0.000163" iyz="-3.9e-05" ixz="0.000681"/>
  </inertial>
  <visual>
    <origin xyz="0.25259 0.310658 -0.447478" rpy="0 0 0"/>
    <geometry>
      <mesh filename="package://ERC22_URDF_description/meshes/Left_leg_double_1.stl" scale="0.001 0.001 0.001"/>
    </geometry>
    <material name="silver"/>
  </visual>
  <collision>
    <origin xyz="0.25259 0.310658 -0.447478" rpy="0 0 0"/>
    <geometry>
      <mesh filename="package://ERC22_URDF_description/meshes/Left_leg_double_1.stl" scale="0.001 0.001 0.001"/>
    </geometry>
  </collision>
</link>

<link name="WLB_supp_1">
  <inertial>
    <origin xyz="0.002903499921163455 0.03188196836487295 -0.06601877471300915" rpy="0 0 0"/>
    <mass value="0.05726725763420208"/>
    <inertia ixx="0.000209" iyy="0.000168" izz="5.9e-05" ixy="-3e-06" iyz="5.6e-05" ixz="6e-06"/>
  </inertial>
  <visual>
    <origin xyz="0.425604 0.392158 -0.361347" rpy="0 0 0"/>
    <geometry>
      <mesh filename="package://ERC22_URDF_description/meshes/WLB_supp_1.stl" scale="0.001 0.001 0.001"/>
    </geometry>
    <material name="silver"/>
  </visual>
  <collision>
    <origin xyz="0.425604 0.392158 -0.361347" rpy="0 0 0"/>
    <geometry>
      <mesh filename="package://ERC22_URDF_description/meshes/WLB_supp_1.stl" scale="0.001 0.001 0.001"/>
    </geometry>
  </collision>
</link>

<link name="WLB_1">
  <inertial>
    <origin xyz="-0.000157436619810436 -0.04853467078007917 -7.357831886489752e-06" rpy="0 0 0"/>
    <mass value="0.821177966951147"/>
    <inertia ixx="0.002537" iyy="0.004162" izz="0.002536" ixy="6e-06" iyz="0.0" ixz="0.0"/>
  </inertial>
  <visual>
    <origin xyz="0.418419 0.373675 -0.203511" rpy="0 0 0"/>
    <geometry>
      <mesh filename="package://ERC22_URDF_description/meshes/WLB_1.stl" scale="0.001 0.001 0.001"/>
    </geometry>
    <material name="silver"/>
  </visual>
  <collision>
    <origin xyz="0.418419 0.373675 -0.203511" rpy="0 0 0"/>
    <geometry>
      <mesh filename="package://ERC22_URDF_description/meshes/WLB_1.stl" scale="0.001 0.001 0.001"/>
    </geometry>
  </collision>
</link>

<link name="WLM_1">
  <inertial>
    <origin xyz="-9.162353946969015e-07 -0.04483339443239004 -7.236476196326169e-07" rpy="0 0 0"/>
    <mass value="0.8017382692848779"/>
    <inertia ixx="0.002476" iyy="0.004159" izz="0.002476" ixy="0.0" iyz="0.0" ixz="0.0"/>
  </inertial>
  <visual>
    <origin xyz="0.017943 0.380158 -0.210814" rpy="0 0 0"/>
    <geometry>
      <mesh filename="package://ERC22_URDF_description/meshes/WLM_1.stl" scale="0.001 0.001 0.001"/>
    </geometry>
    <material name="silver"/>
  </visual>
  <collision>
    <origin xyz="0.017943 0.380158 -0.210814" rpy="0 0 0"/>
    <geometry>
      <mesh filename="package://ERC22_URDF_description/meshes/WLM_1.stl" scale="0.001 0.001 0.001"/>
    </geometry>
  </collision>
</link>

<link name="WLF_1">
  <inertial>
    <origin xyz="0.0002756316511097756 -0.03824713622289272 6.33834755653373e-06" rpy="0 0 0"/>
    <mass value="0.8211285553800025"/>
    <inertia ixx="0.002536" iyy="0.004162" izz="0.002535" ixy="-1.2e-05" iyz="-0.0" ixz="-0.0"/>
  </inertial>
  <visual>
    <origin xyz="-0.396484 0.364675 -0.225675" rpy="0 0 0"/>
    <geometry>
      <mesh filename="package://ERC22_URDF_description/meshes/WLF_1.stl" scale="0.001 0.001 0.001"/>
    </geometry>
    <material name="silver"/>
  </visual>
  <collision>
    <origin xyz="-0.396484 0.364675 -0.225675" rpy="0 0 0"/>
    <geometry>
      <mesh filename="package://ERC22_URDF_description/meshes/WLF_1.stl" scale="0.001 0.001 0.001"/>
    </geometry>
  </collision>
</link>

<link name="WRF_supp_1">
  <inertial>
    <origin xyz="0.0016416095063517266 -0.037844265968987045 -0.0964909033672866" rpy="0 0 0"/>
    <mass value="0.06594197827899752"/>
    <inertia ixx="0.000199" iyy="0.000176" izz="3.9e-05" ixy="-0.0" iyz="3e-06" ixz="3e-06"/>
  </inertial>
  <visual>
    <origin xyz="-0.393337 -0.386841 -0.36517" rpy="0 0 0"/>
    <geometry>
      <mesh filename="package://ERC22_URDF_description/meshes/WRF_supp_1.stl" scale="0.001 0.001 0.001"/>
    </geometry>
    <material name="silver"/>
  </visual>
  <collision>
    <origin xyz="-0.393337 -0.386841 -0.36517" rpy="0 0 0"/>
    <geometry>
      <mesh filename="package://ERC22_URDF_description/meshes/WRF_supp_1.stl" scale="0.001 0.001 0.001"/>
    </geometry>
  </collision>
</link>

<link name="WRB_supp_1">
  <inertial>
    <origin xyz="0.00278870991833563 -0.031841488157177744 -0.06644057204157627" rpy="0 0 0"/>
    <mass value="0.05751878988929576"/>
    <inertia ixx="0.000211" iyy="0.000171" izz="5.9e-05" ixy="3e-06" iyz="-5.6e-05" ixz="6e-06"/>
  </inertial>
  <visual>
    <origin xyz="0.425538 -0.396591 -0.36149" rpy="0 0 0"/>
    <geometry>
      <mesh filename="package://ERC22_URDF_description/meshes/WRB_supp_1.stl" scale="0.001 0.001 0.001"/>
    </geometry>
    <material name="silver"/>
  </visual>
  <collision>
    <origin xyz="0.425538 -0.396591 -0.36149" rpy="0 0 0"/>
    <geometry>
      <mesh filename="package://ERC22_URDF_description/meshes/WRB_supp_1.stl" scale="0.001 0.001 0.001"/>
    </geometry>
  </collision>
</link>

<link name="WRF_1">
  <inertial>
    <origin xyz="0.00022243797779680774 0.030856418914129602 5.266976624562769e-06" rpy="0 0 0"/>
    <mass value="0.7923140233383783"/>
    <inertia ixx="0.002447" iyy="0.004158" izz="0.002447" ixy="1.2e-05" iyz="0.0" ixz="-0.0"/>
  </inertial>
  <visual>
    <origin xyz="-0.396266 -0.375303 -0.2252" rpy="0 0 0"/>
    <geometry>
      <mesh filename="package://ERC22_URDF_description/meshes/WRF_1.stl" scale="0.001 0.001 0.001"/>
    </geometry>
    <material name="silver"/>
  </visual>
  <collision>
    <origin xyz="-0.396266 -0.375303 -0.2252" rpy="0 0 0"/>
    <geometry>
      <mesh filename="package://ERC22_URDF_description/meshes/WRF_1.stl" scale="0.001 0.001 0.001"/>
    </geometry>
  </collision>
</link>

<link name="WRM_1">
  <inertial>
    <origin xyz="-4.796690451780439e-07 0.04421440445825542 -3.055120773864939e-07" rpy="0 0 0"/>
    <mass value="0.8108718866431287"/>
    <inertia ixx="0.002505" iyy="0.004161" izz="0.002505" ixy="0.0" iyz="0.0" ixz="0.0"/>
  </inertial>
  <visual>
    <origin xyz="0.017751 -0.384591 -0.211299" rpy="0 0 0"/>
    <geometry>
      <mesh filename="package://ERC22_URDF_description/meshes/WRM_1.stl" scale="0.001 0.001 0.001"/>
    </geometry>
    <material name="silver"/>
  </visual>
  <collision>
    <origin xyz="0.017751 -0.384591 -0.211299" rpy="0 0 0"/>
    <geometry>
      <mesh filename="package://ERC22_URDF_description/meshes/WRM_1.stl" scale="0.001 0.001 0.001"/>
    </geometry>
  </collision>
</link>

<link name="WRB_1">
  <inertial>
    <origin xyz="-1.0298475141001795e-06 0.04853448757279211 4.442527895276438e-07" rpy="0 0 0"/>
    <mass value="0.8211769381894314"/>
    <inertia ixx="0.002537" iyy="0.004163" izz="0.002537" ixy="0.0" iyz="0.0" ixz="0.0"/>
  </inertial>
  <visual>
    <origin xyz="0.41828 -0.378107 -0.203657" rpy="0 0 0"/>
    <geometry>
      <mesh filename="package://ERC22_URDF_description/meshes/WRB_1.stl" scale="0.001 0.001 0.001"/>
    </geometry>
    <material name="silver"/>
  </visual>
  <collision>
    <origin xyz="0.41828 -0.378107 -0.203657" rpy="0 0 0"/>
    <geometry>
      <mesh filename="package://ERC22_URDF_description/meshes/WRB_1.stl" scale="0.001 0.001 0.001"/>
    </geometry>
  </collision>
</link>

<link name="Right_leg_double_1">
  <inertial>
    <origin xyz="-0.01841993942514597 0.06805532100441675 -0.08940771566700395" rpy="0 0 0"/>
    <mass value="0.1333867163635017"/>
    <inertia ixx="0.000513" iyy="0.00308" izz="0.00264" ixy="0.000152" iyz="-1.5e-05" ixz="0.000714"/>
  </inertial>
  <visual>
    <origin xyz="0.252596 -0.314341 -0.447766" rpy="0 0 0"/>
    <geometry>
      <mesh filename="package://ERC22_URDF_description/meshes/Right_leg_double_1.stl" scale="0.001 0.001 0.001"/>
    </geometry>
    <material name="silver"/>
  </visual>
  <collision>
    <origin xyz="0.252596 -0.314341 -0.447766" rpy="0 0 0"/>
    <geometry>
      <mesh filename="package://ERC22_URDF_description/meshes/Right_leg_double_1.stl" scale="0.001 0.001 0.001"/>
    </geometry>
  </collision>
</link>

<joint name="Revolucion34" type="continuous">
  <origin xyz="0.393441 -0.383158 0.365642" rpy="0 0 0"/>
  <parent link="base_link"/>
  <child link="WLF_supp_1"/>
  <axis xyz="-0.022692 -0.0 0.999743"/>
</joint>

<joint name="Revolucion35" type="continuous">
  <origin xyz="-0.25259 -0.310658 0.447478" rpy="0 0 0"/>
  <parent link="base_link"/>
  <child link="Left_leg_double_1"/>
  <axis xyz="-0.0 1.0 0.0"/>
</joint>

<joint name="Revolucion36" type="continuous">
  <origin xyz="-0.173014 -0.0815 -0.086131" rpy="0 0 0"/>
  <parent link="Left_leg_double_1"/>
  <child link="WLB_supp_1"/>
  <axis xyz="0.045096 0.0 -0.998983"/>
</joint>

<joint name="Revolucion37" type="continuous">
  <origin xyz="0.007185 0.018483 -0.157836" rpy="0 0 0"/>
  <parent link="WLB_supp_1"/>
  <child link="WLB_1"/>
  <axis xyz="-0.003219 -0.999995 -0.000145"/>
</joint>

<joint name="Revolucion38" type="continuous">
  <origin xyz="0.234647 -0.0695 -0.236664" rpy="0 0 0"/>
  <parent link="Left_leg_double_1"/>
  <child link="WLM_1"/>
  <axis xyz="-0.0 1.0 0.0"/>
</joint>

<joint name="Revolucion39" type="continuous">
  <origin xyz="0.003043 0.018483 -0.139967" rpy="0 0 0"/>
  <parent link="WLF_supp_1"/>
  <child link="WLF_1"/>
  <axis xyz="0.00721 -0.999974 0.000164"/>
</joint>

<joint name="Revolucion40" type="continuous">
  <origin xyz="0.393337 0.386841 0.36517" rpy="0 0 0"/>
  <parent link="base_link"/>
  <child link="WRF_supp_1"/>
  <axis xyz="0.021515 -0.0 -0.999769"/>
</joint>

<joint name="Revolucion41" type="continuous">
  <origin xyz="-0.172942 0.08225 -0.086276" rpy="0 0 0"/>
  <parent link="Right_leg_double_1"/>
  <child link="WRB_supp_1"/>
  <axis xyz="-0.045935 0.0 0.998944"/>
</joint>

<joint name="Revolucion42" type="continuous">
  <origin xyz="0.002929 -0.011538 -0.13997" rpy="0 0 0"/>
  <parent link="WRF_supp_1"/>
  <child link="WRF_1"/>
  <axis xyz="-0.00721 -0.999974 -0.000155"/>
</joint>

<joint name="Revolucion43" type="continuous">
  <origin xyz="0.234845 0.07025 -0.236467" rpy="0 0 0"/>
  <parent link="Right_leg_double_1"/>
  <child link="WRM_1"/>
  <axis xyz="0.0 1.0 -0.0"/>
</joint>

<joint name="Revolucion44" type="continuous">
  <origin xyz="0.007258 -0.018484 -0.157833" rpy="0 0 0"/>
  <parent link="WRB_supp_1"/>
  <child link="WRB_1"/>
  <axis xyz="-0.0 -1.0 0.0"/>
</joint>

<joint name="Revolucion45" type="continuous">
  <origin xyz="-0.252596 0.314341 0.447766" rpy="0 0 0"/>
  <parent link="base_link"/>
  <child link="Right_leg_double_1"/>
  <axis xyz="0.0 1.0 -0.0"/>
</joint>

</robot>
